
  <!-- Reference for all paramteres -->
  <!--https://mujoco.readthedocs.io/en/stable/XMLreference.html-->
  <!-- File examples: -->
  <!-- https://github.com/google-deepmind/mujoco_menagerie/blob/main/trossen_vx300s/vx300s.xml -->
  <!-- https://github.com/google-deepmind/mujoco_menagerie/blob/main/aloha/aloha.xml -->
  <!-- https://github.com/google-deepmind/mujoco_menagerie/blob/main/franka_emika_panda/panda.xml -->
  <!-- https://github.com/jeongeun980906/lerobot-mujoco-tutorial/blob/master/asset/robotis_omy/omy.xml -->

<mujoco model="PAR6_URDF">
  <compiler angle="radian" autolimits="true"/>

  <option integrator="implicitfast"/>

  <!-- Default -->
  <default>
    <default class="Y">
      <joint range="-6.28319 6.28319" armature="0.001" damping="25.0" frictionloss="1.5"/>
      <position kp="500" forcerange="-300 300" ctrlrange="-6.28319 6.28319"/>
    </default>
    <default class="MSG_gripper">
      <joint armature="0.1" damping="10.0" frictionloss="0"/>
      <position forcerange="-50 50" ctrlrange="-0.0525 0" kp="100"/>
    </default>
  </default>

  <asset>
    <mesh name="base_link" file="base_link.STL" scale="1 1 1"/>
    <mesh name="shoulder" file="shoulder.STL" scale="1 1 1"/>
    <mesh name="upper_arm" file="upper_arm.STL" scale="1 1 1"/>
    <mesh name="elbow" file="elbow.STL" scale="1 1 1"/>
    <mesh name="lower_arm" file="lower_arm.STL" scale="1 1 1"/>
    <mesh name="wrist" file="wrist.STL" scale="1 1 1"/>
    <mesh name="gripper" file="gripper.STL" scale="1 1 1"/>
    <mesh name="jaw1" file="jaw1.STL" scale="1 1 1"/>
    <mesh name="jaw2" file="jaw2.STL" scale="1 1 1"/>
  </asset>

  <worldbody>
    <geom type="mesh" rgba="0.79216 0.81961 0.93333 1" mesh="base_link"/>
    <body name="shoulder">
      <inertial pos="0.0065681 0.029094 0.099551" quat="0.438732 0.449118 -0.631911 0.454418" mass="1.993" diaginertia="0.00122723 0.00100741 0.000509712"/>
      <joint name="shoulder_JOINT" pos="0 0 0" axis="0 0 -1" class="Y"/>
      <geom type="mesh" rgba="0.79216 0.81961 0.93333 1" mesh="shoulder"/>
      <body name="upper_arm" pos="0.023421 0 0.1105" quat="0.707105 -0.707108 0 0">
        <inertial pos="-0.0085493 -0.071342 0.041639" quat="0.419414 0.451905 -0.587174 0.5245" mass="1.332" diaginertia="0.00165491 0.00161199 0.0002696"/>
        <joint name="upper_arm_JOINT" pos="0 0 0" axis="0 0 1" class="Y"/>
        <geom type="mesh" rgba="0.79216 0.81961 0.93333 1" mesh="upper_arm"/>
        <body name="elbow" pos="0 -0.18 0" quat="-2.59734e-06 0.707105 -0.707108 2.59735e-06">
          <inertial pos="0.015551 -0.019113 -0.0015332" quat="0.29143 0.634234 -0.265884 0.664922" mass="0.681" diaginertia="0.000816953 0.000689258 0.000454939"/>
          <joint name="elbow_JOINT" pos="0 0 0" axis="0 0 -1" class="Y"/>
          <geom type="mesh" rgba="0.79216 0.81961 0.93333 1" mesh="elbow"/>
          <body name="lower_arm" pos="0.0435 0 0" quat="-2.59734e-06 -2.59735e-06 -0.707108 -0.707105">
            <inertial pos="0.00052734 -0.010166 -0.092593" quat="0.959861 -0.262793 -0.0146171 -0.0969154" mass="0.579" diaginertia="0.000384758 0.000361865 0.000214287"/>
            <joint name="lower_arm_JOINT" pos="0 0 0" axis="0 0 -1" class="Y"/>
            <geom type="mesh" rgba="0.79216 0.81961 0.93333 1" mesh="lower_arm"/>
            <body name="wrist" pos="0 0 -0.177" quat="0.707105 -0.707108 0 0">
              <inertial pos="-1.5461e-06 -0.0031485 0.00019393" quat="0.721593 0.692318 0.000460117 -0.00048133" mass="0.523" diaginertia="0.00018083 0.000175719 0.000106091"/>
              <joint name="wrist_JOINT" pos="0 0 0" axis="0 0 1" class="Y"/>
              <geom type="mesh" rgba="0.79216 0.81961 0.93333 1" mesh="wrist"/>
              <body name="gripper" quat="0.707105 0.707108 0 0">
                <inertial pos="-0.0064247 0.000282669 -0.0695192" quat="0.700694 0.703416 0.0814468 -0.0871836" mass="0.347623" diaginertia="0.000141544 0.000129702 2.45301e-05"/>
                <joint name="gripper_JOINT" pos="0 0 0" axis="0 0 -1" class="Y"/>
                <geom type="mesh" rgba="0.79216 0.81961 0.93333 1" mesh="gripper"/>
                            <!-- Camera center -->
                <body name="camera_center" pos="0.0 -0.09 0.1">
                    <geom size="0.005 0.005 0.005" pos="0. 0. 0."
                        contype="0" conaffinity="0"
                        type="box" rgba="1.00 0.00 0.0 0" />
                    <camera name="egocentric" pos="0 0 0" xyaxes="-1 0 0 0 0 1" fovy="90" />
                </body>

                <body name="tcp_link" pos="0 -0.22 0">


                  <!-- Tool Center Point (main reference for control, IK, rewards) -->
                  <site name="tcp"
                        pos="0 0 0"
                        size="0.005"
                        rgba="1 0 0 1"/>


                  <geom type="capsule" fromto="0 0 -0.5 0 0 0.5" size="0.01" rgba="1.0 0.2 0.2 0.0" contype="0" conaffinity="0"/>
                </body>

                <body name="jaw1" pos="0.02835 0 -0.1409" quat="1.34924e-11 3.67321e-06 -1 -3.67321e-06">
                  <inertial pos="0.0016848 -0.059152 -0.053962" quat="0.98197 0.171875 0.0156016 -0.0771347" mass="0.020716" diaginertia="1.62283e-05 1.1144e-05 6.39767e-06"/>
                  <joint name="jaw1_JOINT" pos="0 0 0" axis="0 -1 0" type="slide" range="-0.0525 0" class="MSG_gripper"/>
                  <geom type="mesh"
                        mesh="jaw1"
                        rgba="0.29804 0.29804 0.29804 1"
                        friction="1.2 0.3 0.001"
                        solref="0.002 1"
                        solimp="0.9 0.95 0.001"/>
                </body>

                <body name="jaw2" pos="0.02835 0 -0.1409" quat="1.34924e-11 3.67321e-06 -1 -3.67321e-06">
                  <inertial pos="0.0016605 0.059282 -0.050421" quat="0.994665 0.0689527 0.0499866 0.0582113" mass="0.020666" diaginertia="1.60561e-05 1.06891e-05 6.58103e-06"/>
                  <joint name="jaw2_JOINT" pos="0 0 0" axis="0 -1 0" type="slide" range="0 0.0525" class="MSG_gripper"/>
                  <geom type="mesh"
                        mesh="jaw2"
                        rgba="0.29804 0.29804 0.29804 1"
                        friction="1.2 0.3 0.001"
                        solref="0.002 1"
                        solimp="0.9 0.95 0.001"/>
                </body>  
                
              </body>
            </body>
          </body>
        </body>
      </body>
    </body>
  </worldbody>


  <!-- Exclude contact information -->
  <contact>
    <exclude body1="world" body2="shoulder"/>
  </contact>

  <!-- Gripper fingers are parallel -->
  <equality>
    <joint joint1="jaw2_JOINT" joint2="jaw1_JOINT" polycoef="0 -1 0 0 0"/>
  </equality>

  <!-- Define actuators -->
  <actuator>
    <position name="actuator_joint1" joint="shoulder_JOINT" class="Y"/>
    <position name="actuator_joint2" joint="upper_arm_JOINT" class="Y"/>
    <position name="actuator_joint3" joint="elbow_JOINT" class="Y"/>
    <position name="actuator_joint4" joint="lower_arm_JOINT" class="Y"/>
    <position name="actuator_joint5" joint="wrist_JOINT" class="Y"/>
    <position name="actuator_joint6" joint="gripper_JOINT" class="Y"/>

    <position name="actuator_rh_r1" joint="jaw1_JOINT" class="MSG_gripper"/>


  </actuator>

</mujoco>



